<robot
  name="amr_urdf_v3">
  <link
    name="base_link">
    <inertial>
      <origin
        xyz="-0.0010176740304066 -0.00160349371590989 0.0789280634320502"
        rpy="0 0 0" />
      <mass
        value="4.06425207718803" />
      <inertia
        ixx="0.011888264404141"
        ixy="2.19115724720298E-05"
        ixz="4.36799830555761E-06"
        iyy="0.0130181756354306"
        iyz="-5.43500412982131E-07"
        izz="0.018709872116092" />
    </inertial>
    <visual>
      <origin
        xyz="0 0 0" 
        rpy="0 0 0" />
      <geometry>
        <mesh
          filename="package://amr_urdf_v3/meshes/base_link.STL" />
      </geometry>
      <material
        name="">
        <color
          rgba="0.752941176470588 0.752941176470588 0.752941176470588 1" />
      </material>
    </visual>
    <collision>
      <origin
        xyz="0 0 0"
        rpy="0 0 0" />
      <geometry>
        <mesh
          filename="package://amr_urdf_v3/meshes/base_link.STL" />
      </geometry>
    </collision>
  </link>
  
  <!--
  <joint
    name="camera_joint"
    type="fixed">
    <origin
      xyz="0.1335 -0.00020556 0.2257"
      rpy="0 0 0" />
    <parent
      link="base_link" />
    <child
      link="camera_link" />
    <axis
      xyz="0 0 0" />
  </joint>
  -->
  
  
  <link
    name="right_motor_link">
    <inertial>
      <origin
        xyz="0.00798642968233698 -1.53544465665456E-18 0"
        rpy="0 0 0" />
      <mass
        value="0.0365559400762103" />
      <inertia
        ixx="3.01327681839806E-05"
        ixy="-8.20240559215681E-21"
        ixz="-5.35914288737187E-21"
        iyy="1.63979555484106E-05"
        iyz="6.00196961851436E-21"
        izz="1.63979555484106E-05" />
    </inertial>
    <visual>
      <origin
        xyz="0 0 0"
        rpy="0 0 0" />
      <geometry>
        <mesh
          filename="package://amr_urdf_v3/meshes/right_motor_link.STL" />
      </geometry>
      <material
        name="">
        <color
          rgba="0.792156862745098 0.819607843137255 0.933333333333333 1" />
      </material>
    </visual>
    <collision>
      <origin
        xyz="0 0 0"
        rpy="0 0 0" />
      <geometry>
        <mesh
          filename="package://amr_urdf_v3/meshes/right_motor_link.STL" />
      </geometry>
    </collision>
  </link>
  
  <joint
    name="right_motor_joint"
    type="continuous">
    <origin
      xyz="0 -0.15773 -0.0299999999999993"
      rpy="0 0 -1.57079632679489" />
    <parent
      link="base_link" />
    <child
      link="right_motor_link" />
    <axis
      xyz="-1 0 0" /> 
    <limit
      effort="300"
      velocity="300" />
  </joint>
  <link
    name="left_motor_link">
    <inertial>
      <origin
        xyz="0.00798642968233701 9.04521983301436E-13 -1.17392207066302E-13"
        rpy="0 0 0" />
      <mass
        value="0.0365559400762103" />
      <inertia
        ixx="3.01327681839806E-05"
        ixy="8.04028215445792E-22"
        ixz="1.87589665538517E-21"
        iyy="1.63979555484106E-05"
        iyz="9.47686957878753E-21"
        izz="1.63979555484106E-05" />
    </inertial>
    <visual>
      <origin
        xyz="0 0 0"
        rpy="0 0 0" />
      <geometry>
        <mesh
          filename="package://amr_urdf_v3/meshes/left_motor_link.STL" />
      </geometry>
      <material
        name="">
        <color
          rgba="0.792156862745098 0.819607843137255 0.933333333333333 1" />
      </material>
    </visual>
    <collision>
      <origin
        xyz="0 0 0"
        rpy="0 0 0" />
      <geometry>
        <mesh
          filename="package://amr_urdf_v3/meshes/left_motor_link.STL" />
      </geometry>
    </collision>
  </link>
  <joint
    name="left_motor_joint"
    type="continuous">
    <origin
      xyz="0 0.157729999998498 -0.0300000000003936"
      rpy="0 0 1.5707963267949" />
    <parent
      link="base_link" />
    <child
      link="left_motor_link" />
    <axis
      xyz="1 0 0" />
    <limit
      effort="300"
      velocity="300" />
  </joint>


<gazebo>
  <plugin name="diff_drive" filename="libgazebo_ros_diff_drive.so">
    <ros>
      <namespace>/demo</namespace>
    </ros>

    <left_joint>left_motor_joint</left_joint>
    <right_joint>right_motor_joint</right_joint>

    <wheel_separation>0.35</wheel_separation> 
    <wheel_diameter>0.12</wheel_diameter>

    <max_wheel_torque>20</max_wheel_torque>
    <max_wheel_acceleration>1.0</max_wheel_acceleration>

    <publish_odom>true</publish_odom>
    <publish_odom_tf>true</publish_odom_tf> 
    <publish_wheel_tf>true</publish_wheel_tf>

    <odometry_frame>odom</odometry_frame>
    <robot_base_frame>base_link</robot_base_frame>
  </plugin>
</gazebo>


<ros2_control name="ros2_control_diffdrive" type="system">
        <hardware>
            <plugin>ros2_control_demo_example_2/DiffBotSystemHardware</plugin>
            <param name="left_wheel_name">left_motor_joint</param> 
            <param name="right_wheel_name">right_motor_joint</param> 
            <param name="enc_l_counts_per_rev">362</param> <!--380.. OR 355-->
            <param name="enc_r_counts_per_rev">355</param> <!--366-->
        </hardware> 

        <joint name = "left_motor_joint">
            <command_interface name = "velocity">
                <param name = "min">-14</param> 
                <param name = "max">14</param>
            </command_interface>
            <state_interface name = "position"/>
            <state_interface name = "velocity"/> 
        </joint>

        <joint name = "right_motor_joint">
            <command_interface name = "velocity">
                <param name = "min">-14</param> <!--38-->
                <param name = "max">14</param>  
            </command_interface>
            <state_interface name = "position"/>
            <state_interface name = "velocity"/>
        </joint>
  </ros2_control>


  <link
    name="back_caster_swivel_link">
    <inertial>
      <origin
        xyz="1.38777878078145E-17 2.42739208054735E-17 -0.00859163496952492"
        rpy="0 0 0" />
      <mass
        value="0.0342071620853004" />
      <inertia
        ixx="5.59165765821269E-06"
        ixy="5.99062099685569E-14"
        ixz="2.42813785033998E-21"
        iyy="4.62417593549193E-06"
        iyz="1.20669683067244E-20"
        izz="6.14879674609405E-06" />
    </inertial>
    <visual>
      <origin
        xyz="0 0 0"
        rpy="0 0 0" />
      <geometry>
        <mesh
          filename="package://amr_urdf_v3/meshes/back_caster_swivel_link.STL" />
      </geometry>
      <material
        name="">
        <color
          rgba="0.647058823529412 0.619607843137255 0.588235294117647 1" />
      </material>
    </visual>
    <collision>
      <origin
        xyz="0 0 0"
        rpy="0 0 0" />
      <geometry>
        <mesh
          filename="package://amr_urdf_v3/meshes/back_caster_swivel_link.STL" />
      </geometry>
    </collision>
  </link>
  <joint
    name="back_caster_swivel_joint"
    type="continuous">
    <origin
      xyz="-0.113 0 -0.02125"
      rpy="0 0 0" />
    <parent
      link="base_link" />
    <child
      link="back_caster_swivel_link" />
    <axis
      xyz="0 0 1" />
  </joint>
  <link
    name="back_caster_wheel_link">
    <inertial>
      <origin
        xyz="-1.38777878078145E-17 -1.02104301768038E-18 0"
        rpy="0 0 0" />
      <mass
        value="0.00910029124350843" />
      <inertia
        ixx="6.69349690057285E-07"
        ixy="-3.53100216598249E-21"
        ixz="1.25313985392662E-23"
        iyy="1.10476081341001E-06"
        iyz="1.70394260036174E-22"
        izz="6.69349690057285E-07" />
    </inertial>
    <visual>
      <origin
        xyz="0 0 0"
        rpy="0 0 0" />
      <geometry>
        <mesh
          filename="package://amr_urdf_v3/meshes/back_caster_wheel_link.STL" />
      </geometry>
      <material
        name="">
        <color
          rgba="0.101960784313725 0.101960784313725 0.101960784313725 1" />
      </material>
    </visual>
    <collision>
      <origin
        xyz="0 0 0"
        rpy="0 0 0" />
      <geometry>
        <mesh
          filename="package://amr_urdf_v3/meshes/back_caster_wheel_link.STL" />
      </geometry>
    </collision>
  </link>
  <joint
    name="back_caster_wheel_joint"
    type="continuous">
    <origin
      xyz="0 0 -0.02825"
      rpy="0 0 0" />
    <parent
      link="back_caster_swivel_link" />
    <child
      link="back_caster_wheel_link" />
    <axis
      xyz="0 -1 0" />
  </joint>
  <link
    name="front_caster_swivel_link">
    <inertial>
      <origin
        xyz="-1.38777878078145E-17 -1.11242347561298E-17 -0.00859163496952491"
        rpy="0 0 0" />
      <mass
        value="0.0342071620853004" />
      <inertia
        ixx="5.59165765821268E-06"
        ixy="5.99061993031957E-14"
        ixz="-1.9198369614391E-21"
        iyy="4.62417593549192E-06"
        iyz="-1.1528313380055E-20"
        izz="6.14879674609405E-06" />
    </inertial>
    <visual>
      <origin
        xyz="0 0 0"
        rpy="0 0 0" />
      <geometry>
        <mesh
          filename="package://amr_urdf_v3/meshes/front_caster_swivel_link.STL" />
      </geometry>
      <material
        name="">
        <color
          rgba="0.647058823529412 0.619607843137255 0.588235294117647 1" />
      </material>
    </visual>
    <collision>
      <origin
        xyz="0 0 0"
        rpy="0 0 0" />
      <geometry>
        <mesh
          filename="package://amr_urdf_v3/meshes/front_caster_swivel_link.STL" />
      </geometry>
    </collision>
  </link>
  <joint
    name="front_caster_swivel_joint"
    type="continuous">
    <origin
      xyz="0.113 0 -0.02125"
      rpy="0 0 0" />
    <parent
      link="base_link" />
    <child
      link="front_caster_swivel_link" />
    <axis
      xyz="0 0 1" />
  </joint>
  <link
    name="front_caster_wheel_link">
    <inertial>
      <origin
        xyz="0 -9.12589751828138E-20 0"
        rpy="0 0 0" />
      <mass
        value="0.00910029124350843" />
      <inertia
        ixx="6.69349690057285E-07"
        ixy="3.95110387068532E-22"
        ixz="9.85766645615961E-25"
        iyy="1.10476081341001E-06"
        iyz="1.68736474715625E-22"
        izz="6.69349690057285E-07" />
    </inertial>
    <visual>
      <origin
        xyz="0 0 0"
        rpy="0 0 0" />
      <geometry>
        <mesh
          filename="package://amr_urdf_v3/meshes/front_caster_wheel_link.STL" />
      </geometry>
      <material
        name="">
        <color
          rgba="0.101960784313725 0.101960784313725 0.101960784313725 1" />
      </material>
    </visual>
    <collision>
      <origin
        xyz="0 0 0"
        rpy="0 0 0" />
      <geometry>
        <mesh
          filename="package://amr_urdf_v3/meshes/front_caster_wheel_link.STL" />
      </geometry>
    </collision>
  </link>
  <joint
    name="front_caster_wheel_joint"
    type="continuous">
    <origin
      xyz="0 0 -0.02825"
      rpy="0 0 0" />
    <parent
      link="front_caster_swivel_link" />
    <child
      link="front_caster_wheel_link" />
    <axis
      xyz="0 -1 0" />
  </joint>


  <link
    name="imu_link">
    <inertial>
      <origin
        xyz="8.83832534712359E-19 -1.68731665717814E-18 -0.00102130965190103"
        rpy="0 0 0" />
      <mass
        value="0.00514746084847653" />
      <inertia
        ixx="7.93474008155527E-07"
        ixy="6.139231108792E-23"
        ixz="-1.51428536771307E-23"
        iyy="1.00625209716698E-06"
        iyz="-6.83596985419307E-24"
        izz="1.78297175236149E-06" />
    </inertial>
    <visual>
      <origin
        xyz="0 0 0"
        rpy="0 0 0" />
      <geometry>
        <mesh
          filename="package://amr_urdf_v3/meshes/imu_link.STL" />
      </geometry>
      <material
        name="">
        <color
          rgba="0.286274509803922 0.662745098039216 0.329411764705882 1" />
      </material>
    </visual>
    <collision>
      <origin
        xyz="0 0 0"
        rpy="0 0 0" />
      <geometry>
        <mesh
          filename="package://amr_urdf_v3/meshes/imu_link.STL" />
      </geometry>
    </collision>
  </link>

  <joint
    name="imu_joint"
    type="fixed">
    <origin
      xyz="0 0 0.148"
      rpy="0 0 0" />
    <parent
      link="base_link" />
    <child
      link="imu_link" />
    <axis
      xyz="0 0 0" />
  </joint>


 <gazebo reference="imu_link">
  <sensor name="imu_sensor" type="imu">
   <plugin filename="libgazebo_ros_imu_sensor.so" name="imu_plugin">
      <ros>
        <namespace>/demo</namespace>
        <remapping>~/out:=imu</remapping>
      </ros>
      <initial_orientation_as_reference>false</initial_orientation_as_reference>
    </plugin>
    <always_on>true</always_on>
    <update_rate>100</update_rate>
    <visualize>true</visualize>
    <imu>
      <angular_velocity>
        <x>
          <noise type="gaussian">
            <mean>0.0</mean>
            <stddev>2e-4</stddev>
            <bias_mean>0.0000075</bias_mean>
            <bias_stddev>0.0000008</bias_stddev>
          </noise>
        </x>
        <y>
          <noise type="gaussian">
            <mean>0.0</mean>
            <stddev>2e-4</stddev>
            <bias_mean>0.0000075</bias_mean>
            <bias_stddev>0.0000008</bias_stddev>
          </noise>
        </y>
        <z>
          <noise type="gaussian">
            <mean>0.0</mean>
            <stddev>2e-4</stddev>
            <bias_mean>0.0000075</bias_mean>
            <bias_stddev>0.0000008</bias_stddev>
          </noise>
        </z>
      </angular_velocity>
      <linear_acceleration>
        <x>
          <noise type="gaussian">
            <mean>0.0</mean>
            <stddev>1.7e-2</stddev>
            <bias_mean>0.1</bias_mean>
            <bias_stddev>0.001</bias_stddev>
          </noise>
        </x>
        <y>
          <noise type="gaussian">
            <mean>0.0</mean>
            <stddev>1.7e-2</stddev>
            <bias_mean>0.1</bias_mean>
            <bias_stddev>0.001</bias_stddev>
          </noise>
        </y>
        <z>
          <noise type="gaussian">
            <mean>0.0</mean>
            <stddev>1.7e-2</stddev>
            <bias_mean>0.1</bias_mean>
            <bias_stddev>0.001</bias_stddev>
          </noise>
        </z>
      </linear_acceleration>
    </imu>
  </sensor>
</gazebo>





  <link
    name="lidar_link">
    <inertial>
      <origin
        xyz="-0.0119599422907501 0.000420457853612401 -0.0146806721706361"
        rpy="0 0 0" />
      <mass
        value="0.0729132747388752" />
      <inertia
        ixx="1.81540410268974E-05"
        ixy="-3.13526570959607E-07"
        ixz="3.25184596662622E-07"
        iyy="2.39750540545773E-05"
        iyz="1.07178388102884E-08"
        izz="3.9435616182922E-05" />
    </inertial>
    <visual>
      <origin
        xyz="0 0 0"
        rpy="0 0 0" />
      <geometry>
        <mesh
          filename="package://amr_urdf_v3/meshes/lidar_link.STL" />
      </geometry>
      <material
        name="">
        <color
          rgba="0.792156862745098 0.819607843137255 0.933333333333333 1" />
      </material>
    </visual>
    <collision>
      <origin
        xyz="0 0 0"
        rpy="0 0 0" />
      <geometry>
        <mesh
          filename="package://amr_urdf_v3/meshes/lidar_link.STL" />
      </geometry>
    </collision>
  </link>

  <joint
    name="lidar_joint"
    type="fixed">
    <origin
      xyz="0.00699999999889178 0 0.25549999999896"
      rpy="0 0 0" />
    <parent
      link="base_link" />
    <child
      link="lidar_link" />
    <axis
      xyz="0 0 0" />
  </joint>


<gazebo reference="lidar_link">
  <sensor name="laser" type="ray">
    <pose>0 0 0 0 0 0</pose>  
    <!-- <always_on>true</always_on> -->
    <update_rate>20</update_rate>
    <visualize>true</visualize>
    <ray>
      <scan>
        <horizontal>
          <samples>720</samples>
          <resolution>1</resolution>
          <min_angle>-3.1415926</min_angle>
          <max_angle>3.1415926</max_angle>
        </horizontal> 
      </scan>
      <range>
        <min>0.1</min>
        <max>10.0</max>
        <resolution>0.01</resolution>  
      </range>   
     <!-- <noise>   
        <type>gaussian</type>  
        <mean>0.0</mean>
        <stddev>0.01</stddev>
      </noise> -->
    </ray> 
    <plugin name="gazebo_ros_laser_controller" filename="libgazebo_ros_ray_sensor.so">
      <ros>
        <!-- <namespace>/demo</namespace> --> 
        <remapping>~/out:=scan</remapping>
        <!-- <topicName>scan</topicName>  -->
      </ros> 
      <output_type>sensor_msgs/LaserScan</output_type>      
      <frame_name>lidar_link</frame_name>
    </plugin>   
  </sensor>
</gazebo> 
 






  <link
    name="camera_link">
    <inertial>
      <origin
        xyz="-0.0250710998831694 0.000537936695328088 -0.00614946362916749"
        rpy="0 0 0" />
      <mass
        value="0.0313336679699393" />
      <inertia
        ixx="2.27202820665302E-05"
        ixy="-1.32703422540569E-07"
        ixz="-2.86292130544785E-07"
        iyy="4.32636813211046E-06"
        iyz="-4.54549299258422E-09"
        izz="2.21282712614926E-05" />
    </inertial>
    <visual>
      <origin
        xyz="0 0 0"
        rpy="0 0 0" />
      <geometry>
        <mesh
          filename="package://amr_urdf_v3/meshes/camera_link.STL" />
      </geometry>
      <material
        name="">
        <color
          rgba="0.792156862745098 0.819607843137255 0.933333333333333 1" />
      </material>
    </visual>
    <collision>
      <origin
        xyz="0 0 0"
        rpy="0 0 0" />
      <geometry>
        <mesh
          filename="package://amr_urdf_v3/meshes/camera_link.STL" />
      </geometry>
    </collision>
  </link>
  <joint
    name="camera_joint"
    type="fixed">
    <origin
      xyz="0.1335 -0.00020556 0.2257"
      rpy="0 0 0" />
    <parent
      link="base_link" />
    <child
      link="camera_link" />
    <axis
      xyz="0 0 0" />
  </joint>
</robot>
